Workbook
Name IQ_CH: 110000
Name IQ_CQ: 5000
Name IQ_CY: 10000
Name IQ_DAILY: 500000
Name IQ_FH: 100000
Name IQ_FQ: 500
Name IQ_FY: 1000
Name IQ_LTM: 2000
Name IQ_MONTH: 15000
Name IQ_NTM: 6000
Name IQ_WEEK: 50000
Name IQ_YTD: 3000

Sheet WIP list
B5: Pending Items
A7: 1 | B7: Add a decision type " Avoid Revenue Loss" | C7: Done
A8: 2 | B8: Update Decision logics | C8: Done
A9: 3 | B9: Change Continuing Value to value driver formula | C9: Done
A10: 4 | B10: Assign fundamentals to decisions | C10: In progress
A11: 5 | B11: Explain the model and assumptions to Client | C11: Done
A12: 6 | B12: Swap size and fundaments for Cost Savings | C12: Done
A13: 7 | B13: Add margin constraint | C13: Critical
A14: 8 | B14: Run Monte-Carlo | C14: Waiting for the licence
A15: 9 | B15: Add operating cash allowance | C15: Done
A16: 10 | B16: Add inorganic growth and divestment decisions | C16: In progress
A17: 11 | B17: Add manufacturing OH | C17: Done
A18: 12 | B18: Long-term Growth? | C18: No need
A19: 13 | B19: Implementation costs do not impact IC | C19: Done
A20: 14 | B20: List of cards' inputs
A21: 15 | B21: Clean up

Sheet Decision logic
B2: Common Structure (all levers) | K2: Types of Value Creation Decisions
B3: 5 rounds (years), 5 decisions per round
B4: Each decision tied to:
C5: Guiding principle | K5: Overall | M5: Size 1-5 is a differentiation by scale; Fundamentals 1-5 is a diffirentiation by value creation potential and impacts ROIC
C6: Decision category | M6: The amount of cash available for investments is a SUM: ending non-operating cash (allowance for cash on hand) + Debt Raising capacity
C7: Capital / organizational action | M7: Debt raising capacity is based on Credit Rating and DEBT/EBITDA <= 2.0
B8: Impact scored 1–5 to reflect timing, risk, and TSR contribution | M8: Except for SG&A savings, Round 1-3 decisions are impacted by Recession and Recovery scenarios, Round 4 decisions are impacted by Recovery scenario
B10: Grow — Create future value | K10: 1 | L10: Organic | M10: New business, R&D, JVs and Partnerships
B12: Intent: Expand scope, platforms, and long-term TSR upside | K12: 1 | L12: Impact on cash flows: | M12: Revenue, COGS, SGA, Capex
B13: Logic: Capability → commitment → scale → platform leadership | K13: 2 | L13: Investment
B14: Early rounds: R&D, partnerships, bolt-ons (option creation) | M14: Capex as % of base Revenue
B15: Mid rounds: capacity, geography, industrialization (commitment) | M15: Size of investment vary from 1-5 (1-2.5% of Base Revenue)
B16: Late rounds: system integration, ecosystems, large M&A (step-change) | K16: 3 | L16: Value drivers:
B17: Impact: Higher variance; late-round 4–5s | M17: Gross Margin (COGS impact, SGA 5% by defualt)
M18: Short-term growth
M19: Capital Efficiency
K20: 3 | L20: Assumptions and Differentiation
M21: Investment period 1-3 years
M22: Value Drivers are ranked from 1-5 depending on value creation potential
M23: 1 year Revenue = Investment * Capital turns
K25: 2 | L25: Inorganic | M25: In Progress | R25: David: | S25: link synergies to premium paid
S26: % premium paid
S27: % synergies created
B29: Optimize — Improve efficiency and returns
K30: 3 | L30: SG&A/COGS savings | M30: Cost Savings
B31: Intent: Reset cost base and ROIC to fund growth
B32: Logic: Friction removal → structural reset → portfolio cleanup | K32: 1 | L32: Impact on cash flows: | M32: COGS and SGA; Non-operating implementation costs
K33: 2 | L33: Investment | M33: Costs X:1 to full annual savings. For SGA and COGS decisions costs are not capitalized and treated as non-operating expense, do not increase IC, meaning pure increase in ROIC
B34: Early rounds: SG&A, systems, footprint rationalization | M34: For MOH - represent CAPEX and increse IC
B35: Mid rounds: operating model and group turnarounds | M35: Size of Implementation Cost vary from 1-5 (1.0 - 2.5x of Annual savings)
B36: Late rounds: divestments, full automation, capital discipline | K36: 3 | L36: Value drivers: | M36: COGS savings (% of Base revenue)
B37: Impact: Medium risk; consistent 3–4s | M37: SG&A savings (% of Base revenue)
K38: 4 | L38: Assumptions and Differentiation
M39: Investment period 1-3 years
M40: Value Drivers are ranked from 1-5 depending on value creation potential
M41: SG&A are not impacted by macro scenarios
M42: Total SG&A and COGS saving shold not exceed the gap to best-in class margin: 500 bps.
M43: If they do, no incremental increase in margin, only money spent
M44: Savings are not indexed. Decision now values more than next period
K48: 4 | L48: Divestments | M48: Divestments
...

Sheet Cards
C3: DECISION | D3: =Decisions!U6 -> 1
C5: Organic growth / JV / Partnership | D5: =Decisions!AD6 -> 4
C7: Investments (total) | D7: =-Decisions!AG6 -> 800 | E7: $m
C8: Investment period | D8: =Decisions!AE6 -> 2 | E8: years
C9: Revenue 1 year | D9: =INDEX(Decisions!$F$20:$F$24,MATCH($D$5,Decisions!$E$20:$E$24,))*D7 -> 1600 | E9: $m
C10: 5-year growth | D10: =INDEX(Decisions!$H$20:$H$24,MATCH($D$5,Decisions!$E$20:$E$24,)) -> 0.05 | E10: y-o-y
C11: EBITDA | D11: =INDEX(Decisions!$G$20:$G$24,MATCH($D$5,Decisions!$E$20:$E$24,))-Decisions!F44 -> 0.15
C16: DECISION | D16: =Decisions!U12 -> 7
C18: =Decisions!W12 -> SGA savings | D18: =Decisions!AD12 -> 2
C20: Implementation cost | D20: =INDEX(Decisions!L20:L24,MATCH($D$18,Decisions!$E$10:$E$14,)) -> 2.5 | E20: of Annual savings
C21: Investment period | D21: =Decisions!AE12 -> 1 | E21: year
C22: Annual cost savings | D22: =Decisions!AJ12 -> 40 | E22: $m
C29: DECISION | D29: =Decisions!U19 -> 14
C31: =Decisions!W19 -> Sustain Topline
C33: Investments (total) | D33: =-Decisions!AG16 -> 40 | E33: =E7 -> $m
C34: =C8 -> Investment period | D34: =Decisions!AE19 -> 1 | E34: year
C35: No incremental cash flow created
C36: Avoid losing business-as-usual revenue | D36: -0.001 | E36: to the last year

Sheet _CIQHiddenCacheSheet
A1: 2 | B1: BAABTAVMT0NBTAFI/////wFQAQAAAB5DSVEuVFNYOk1HLklRX1NQX0lTU1VFUl9SQVRJTkcBAAAAuFwEAAMAAAACQS0A6jWZ4VNi3ggpTrvhU2LeCA==

Sheet Decisions
E2: Value Drivers | U2: Decision | AS2: For Cards
W3: To be assigned/updated once decisions are confirmed | AB3: Do not change the round order | AC3: Magnifies the scale | AD3: Impact ROI | AH3: Cumulative NPV may not be tied to totals due to Sustain decisions | AS3: Organic Growth | AY3: Optimise (SGA and COGS) | BD3: Sustain
A5: Do not delete | U5: # | V5: Lever | W5: Type of Value Drivers | X5: lesson Learned | Y5: Decision Type | Z5: Decision Name | AA5: Decision Detail | AB5: Round | AC5: Size | AD5: Fundamentals | AE5: Investment period | AF5: Selected | AG5: Investments | AH5: NPV | AI5: ROIC Y10 | AJ5: EBITDA_Y10 | AK5: Archetype | AN5: Impact on share price | AO5: $ | AP5: 5-year TSR | AS5: Revenue 1 year | AT5: 5-year growth | AU5: Investments (total) | AV5: Investment period | AW5: EBIT margin | AY5: Implementation cost | AZ5: Investments | BA5: Investment period | BB5: Annual cost savings | BD5: Implementation cost | BE5: Investments | BF5: Investment period | BG5: Annual cost savings
A6: Organic | E6: Size | U6: 1 | V6: Grow | W6: Organic | X6: 1. Grow profitably | Y6: Expand Manufacturing Footprint | Z6: Mexico Capacity Expansion | AA6: Expand existing Mexican operations to increase capacity for North American OEMs. Nearshoring trend favors this investment with relatively predictable returns. | AB6: 1 | AC6: 3 | AD6: 4 | AE6: 2 | AF6: 0 | AG6: -800 | AH6: 1319.2498 | AI6: 0.21900992 | AJ6: 306.30757 | AK6: accretive with ROIC 15% | AL6: Accretive | AS6: 1600 | AT6: 0.05 | AU6: -800 | AV6: 2 | AW6: 0.11 | AY6: 0 | AZ6: 0 | BA6: 0 | BB6: 0 | BD6: 0 | BE6: 0 | BF6: 0 | BG6: 0
A7: M&A / Divestments | E7: Type | F7: Organic | G7: M&A / Divestments | K7: COGS savings | L7: SGA savings | M7: Manufacturing OH savings | O7: Sustain Topline | U7: 2 | V7: Grow | W7: Organic | X7: 1. Grow profitably | Y7: Scale R&D for Next-Gen Portfolio | Z7: Advanced Powertrain R&D Expansion | AA7: Invest in expanding R&D capabilities for next-generation vehicle powertrains and propulsion systems. This positions Magna to capture growing market share in advanced mobility but requires significant upfront investment with returns materializing over 2-3 years. | AB7: 1 | AC7: 4 | AD7: 4 | AE7: 3 | AF7: 0 | AG7: -1000 | AH7: 1515.6118 | AI7: 0.21900992 | AJ7: 382.88447 | AK7: accretive with ROIC 15% | AL7: Accretive | AN7: Share price as of today | AO7: 52.265643 | AS7: 2000 | AT7: 0.05 | AU7: -1000 | AV7: 3 | AW7: 0.11 | AY7: 0 | AZ7: 0 | BA7: 0 | BB7: 0 | BD7: 0 | BE7: 0 | BF7: 0 | BG7: 0
A8: COGS savings | F8: Investments (Capex) | G8: Inorganic / Discontinued revenue | I8: Premium | K8: COGS savings | O8: Cost | U8: 3 | V8: Grow | W8: Organic | X8: 1. Grow profitably | Y8: Enter New Geography / Market | Z8: Southeast Asia Market Entry | AA8: Establish manufacturing presence in Thailand/Vietnam to serve growing ASEAN automotive market. Lower labor costs and proximity to emerging markets, but execution risk in new geography. | AB8: 1 | AC8: 3 | AD8: 1 | AE8: 2 | AF8: 0 | AG8: -800 | AH8: -161.16516 | AI8: 0.067817533 | AJ8: 125.2016 | AK8: high growth low margin | AL8: Dilutive | AN8: Share price w/o decision as of today | AO8: 49.110547 | AQ8: margin contraction 50 bps revenue decline 1%, recession/recovery offset each other | AS8: 1200 | AT8: 0.03 | AU8: -800 | AV8: 2 | AW8: 0.05 | AY8: 0 | AZ8: 0 | BA8: 0 | BB8: 0 | BD8: 0 | BE8: 0 | BF8: 0 | BG8: 0
A9: SGA savings | F9: as % of Base Revenue | G9: as % of Base Revenue | I9: As % of Base Price (NPV) | K9: as % of Base Revenue | L9: as % of Base Revenue | M9: as % of Base Revenue | O9: as % of Base Revenue | U9: 4 | V9: Grow | W9: Organic | X9: 3. Stay flexible | Y9: JV / Strategic Partnership | Z9: Battery Technology JV | AA9: Form joint venture with battery cell manufacturer to secure supply and develop integrated battery systems. Strategic hedge against vertical integration by OEMs. | AB9: 1 | AC9: 5 | AD9: 2 | AE9: 2 | AF9: 0 | AG9: -1000 | AH9: -250.32915 | AI9: 0.0624 | AJ9: 112 | AK9: low growth bad capital turnover but high margin | AL9: Dilutive | AN9: Future value w/ decisions | AO9: 76.608257 | AP9: 0.079473179 | AS9: 800 | AT9: 0 | AU9: -1000 | AV9: 2 | AW9: 0.1 | AY9: 0 | AZ9: 0 | BA9: 0 | BB9: 0 | BD9: 0 | BE9: 0 | BF9: 0 | BG9: 0
A10: Sustain Topline | E10: 1 | F10: 0.01 | G10: -0.03 | H10: Divestment | K10: 0.001 | L10: 0.001 | M10: 0.001 | O10: 0.001 | U10: 5 | V10: Grow | W10: Organic | X10: 1. Grow profitably | Y10: Expand Manufacturing Footprint | Z10: Concentrated OEM Capacity Investment | AA10: Major capacity investment for an OEM's flagship vehicle program. The OEM has committed to unprecedented volumes and offered favorable terms for exclusive supply. Higher projected returns than diversified approach, with dedicated production lines and simpler logistics. | AB10: 1 | AC10: 4 | AD10: 1 | AE10: 2 | AF10: 0 | AG10: -1000 | AH10: -201.45646 | AI10: 0.067817533 | AJ10: 156.502 | AK10: high growth low margin | AL10: Dilutive | AN10: Future value w/o decisions | AO10: 55.727563 | AP10: 0.012909748 | AS10: 1500 | AT10: 0.03 | AU10: -1000 | AV10: 2 | AW10: 0.05 | AY10: 0 | AZ10: 0 | BA10: 0 | BB10: 0 | BD10: 0 | BE10: 0 | BF10: 0 | BG10: 0
A11: Manufacturing OH savings | E11: 2 | F11: 0.015 | G11: 0.03 | H11: Acquisition | I11: 0.21272727 | J11: 0.21272727 | K11: 0.001 | L11: 0.001 | M11: 0.001 | O11: 0.002 | U11: 6 | V11: Optimize | W11: Manufacturing OH savings | X11: 1. Grow profitably | Y11: Factory of the Future | Z11: Smart Factory Pilot Program | AA11: Implement Industry 4.0 technologies in flagship facility. IoT sensors, AI-driven quality control, and predictive maintenance. Proof of concept for broader rollout. | AB11: 1 | AC11: 2 | AD11: 1 | AE11: 2 | AF11: 0 | AG11: -120 | AH11: 273.50033 | AI11: 0.26 | AJ11: 40 | AK11: Size impacts the amount of savings, Fundamentals - ROI | AL11: Accretive | AS11: 0 | AT11: 0 | AU11: 0 | AV11: 0 | AY11: 0 | AZ11: -120 | BA11: 2 | BB11: 40 | BD11: 0 | BE11: 0 | BF11: 0 | BG11: 0
A12: Share repurchase | E12: 3 | F12: 0.02 | G12: 0.05 | H12: Acquisition | I12: 0.21272727 | K12: 0.002 | L12: 0.002 | M12: 0.002 | O12: 0.003 | U12: 7 | V12: Optimize | W12: SGA savings | X12: 1. Grow profitably | Y12: SG&A Optimization | Z12: Shared Services Consolidation | AA12: Consolidate back-office functions (finance, HR, IT) into regional shared services centers. Upfront investment yields ongoing cost savings. | AB12: 1 | AC12: 2 | AD12: 2 | AE12: 1 | AF12: 0 | AG12: -100 | AH12: 317.80231 | AI12: 0.312 | AJ12: 40 | AK12: Size impacts the amount of savings, Fundamentals - ROI | AL12: Accretive | AS12: 0 | AT12: 0 | AU12: 0 | AV12: 0 | AY12: 2.5 | AZ12: 0 | BA12: 1 | BB12: 40 | BD12: 0 | BE12: 0 | BF12: 0 | BG12: 0
A13: Dividends | E13: 4 | F13: 0.025 | G13: 0.1 | H13: Acquisition | I13: 0.21272727 | K13: 0.003 | L13: 0.003 | M13: 0.003 | O13: 0.004 | U13: 8 | V13: Optimize | W13: COGS savings | X13: 1. Grow profitably | Y13: Global Supply Chain Redesign | Z13: Supplier Dual-Sourcing Initiative | AA13: Establish secondary suppliers for critical components. Increases supply chain resilience and negotiating leverage. Small cost premium offset by risk reduction. | AB13: 1 | AC13: 3 | AD13: 3 | AE13: 1 | AF13: 0 | AG13: -160 | AH13: 678.94108 | AI13: 0.39 | AJ13: 80 | AK13: Size impacts the amount of savings, Fundamentals - ROI | AL13: Accretive | AS13: 0 | AT13: 0 | AU13: 0 | AV13: 0 | AY13: 2 | AZ13: 0 | BA13: 1 | BB13: 80 | BD13: 0 | BE13: 0 | BF13: 0 | BG13: 0
E14: 5 | F14: 0.025 | G14: 0.2 | H14: Acquisition | I14: 0.21272727 | K14: 0.004 | L14: 0.004 | M14: 0.004 | O14: 0.005 | U14: 9 | V14: Optimize | W14: Manufacturing OH savings | X14: 2. Cash is king | Y14: Enterprise Digital Transformation | Z14: ERP System Upgrade | AA14: Launch enterprise-wide Data & ERP Transformation, migrating core ERP to a modern cloud platform while redesigning data architecture, analytics, and end-to-end processes. Enables advanced analytics, AI-driven automation, and materially improved decision-making across the business. | AB14: 1 | AC14: 2 | AD14: 1 | AE14: 2 | AF14: 0 | AG14: -120 | AH14: 273.50033 | AI14: 0.26 | AJ14: 40 | AK14: Size impacts the amount of savings, Fundamentals - ROI | AL14: Accretive | AS14: 0 | AT14: 0 | AU14: 0 | AV14: 0 | AY14: 0 | AZ14: -120 | BA14: 2 | BB14: 40 | BD14: 0 | BE14: 0 | BF14: 0 | BG14: 0
E15: step | F15: 0.005 | K15: 0.001 | L15: 0.001 | M15: 0.001 | O15: 0.001 | U15: 10 | V15: Optimize | W15: SGA savings | X15: 3. Stay flexible | Y15: Organizational Restructure | Z15: Management Delayering | AA15: Execute a management reorganization to de-layer the organization, accelerating decision-making, clarifying accountability, and sustainably reducing overhead. | AB15: 1 | AC15: 2 | AD15: 5 | AE15: 1 | AF15: 0 | AG15: -40 | AH15: 382.80701 | AI15: 0.78 | AJ15: 40 | AK15: Size impacts the amount of savings, Fundamentals - ROI | AL15: Accretive | AS15: 0 | AT15: 0 | AU15: 0 | AV15: 0 | AY15: 1 | AZ15: 0 | BA15: 1 | BB15: 40 | BD15: 0 | BE15: 0 | BF15: 0 | BG15: 0
U16: 11 | V16: Sustain | W16: Sustain Topline | X16: 1. Grow profitably | Y16: Portfolio management (maintenance) | Z16: Customer Diversification Initiative | AA16: Allocate incremental investment to expand sales coverage and key-account capabilities beyond top customers, deliberately diversifying the revenue base and mitigating concentration risk. | AB16: 1 | AC16: 1 | AD16: 1 | AE16: 1 | AF16: 0 | AG16: -40 | AH16: -37.037037 | AI16: 0 | AJ16: 0 | AL16: Accretive | AS16: 0 | AT16: 0 | AU16: 0 | AV16: 0 | AY16: 0 | AZ16: 0 | BA16: 0 | BB16: 0 | BD16: 0 | BE16: -40 | BF16: 1 | BG16: 0 | BH16: No incremental cash flow created Avoid losing business-as-usual revenue -0.1% y-o-y
E17: Fundamentals | F17: Organic | G17: Organic | H17: Organic | K17: COGS savings | L17: SGA savings | M17: Manufacturing OH savings | P17: Organic | Q17: Inorganic | R17: COGS savings | S17: Manufacturing OH savings | U17: 12 | V17: Sustain | W17: COGS savings | X17: 1. Grow profitably | Y17: Talent & Leadership Upskilling | Z17: Technical Talent Development | AA17: Investment in training and development for engineering workforce. Essential to maintain competitive capabilities. Retention and capability building. | AB17: 1 | AC17: 2 | AD17: 1 | AE17: 1 | AF17: 0 | AG17: -120 | AH17: 296.13407 | AI17: 0.26 | AJ17: 40 | AL17: Accretive | AS17: 0 | AT17: 0 | AU17: 0 | AV17: 0 | AY17: 3 | AZ17: 0 | BA17: 0 | BB17: 0 | BD17: 3 | BE17: 0 | BF17: 1 | BG17: 40
F18: Capital efficiency | G18: Gross Margin (only COGS impact) | H18: 5-year growth | I18: EBIT margin | K18: Cost / Annual savings | L18: Cost / Annual savings | M18: Cost / Annual savings | P18: ROIC | Q18: ROIC | R18: ROIC | S18: ROIC | U18: 13 | V18: Sustain | W18: Sustain Topline | X18: 3. Stay flexible | Y18: Risk & Compliance Upgrade | Z18: Cybersecurity Enhancement | AA18: Comprehensive cybersecurity upgrade across IT infrastructure. Essential protection against growing cyber threats. No direct return but prevents catastrophic risk. | AB18: 1 | AC18: 2 | AD18: 1 | AE18: 1 | AF18: 0 | AG18: -80 | AH18: -74.074074 | AI18: 0 | AJ18: 0 | AL18: Accretive | AS18: 0 | AT18: 0 | AU18: 0 | AV18: 0 | AY18: 0 | AZ18: 0 | BA18: 0 | BB18: 0 | BD18: 0 | BE18: -80 | BF18: 1 | BG18: 0 | BH18: No incremental cash flow created Avoid losing business-as-usual revenue -0.1% y-o-y
C19: Note | F19: capital turns | G19: % | H19: CAGR | K19: x | L19: x | U19: 14 | V19: Sustain | W19: Sustain Topline | X19: 1. Grow profitably | Y19: Capital allocation strategy (maintenance) | Z19: Equipment Refresh Program | AA19: Scheduled replacement of aging manufacturing equipment. Maintains reliability and quality. Deferred investment risks production disruptions. | AB19: 1 | AC19: 2 | AD19: 1 | AE19: 1 | AF19: 0 | AG19: -80 | AH19: -74.074074 | AI19: 0 | AJ19: 0 | AL19: Accretive | AS19: 0 | AT19: 0 | AU19: 0 | AV19: 0 | AY19: 0 | AZ19: 0 | BA19: 0 | BB19: 0 | BD19: 0 | BE19: -80 | BF19: 1 | BG19: 0 | BH19: No incremental cash flow created Avoid losing business-as-usual revenue -0.1% y-o-y
C20: high growth low margin | E20: 1 | F20: 1.5 | G20: 0.14 | H20: 0.03 | I20: 0.05 | K20: 3 | L20: 3 | M20: 3 | P20: 0.067817533 | Q20: in progress | R20: 0.26 | S20: 0.26 | U20: 15 | V20: Sustain | W20: SGA savings | X20: 3. Stay flexible | Y20: Risk & Compliance Upgrade | Z20: Environmental Compliance Investment | AA20: Proactive investment to meet upcoming environmental regulations. Mandatory compliance but early investment avoids rushed future spending. | AB20: 1 | AC20: 1 | AD20: 1 | AE20: 1 | AF20: 0 | AG20: -120 | AH20: 296.13407 | AI20: 0.26 | AJ20: 40 | AL20: Accretive | AS20: 0 | AT20: 0 | AU20: 0 | AV20: 0 | AY20: 3 | AZ20: 0 | BA20: 0 | BB20: 0 | BD20: 3 | BE20: 0 | BF20: 1 | BG20: 40
C21: low growth bad capital turnover but high margin | E21: 2 | F21: 0.8 | G21: 0.19 | H21: 0 | I21: 0.1 | K21: 2.5 | L21: 2.5 | M21: 2.5 | P21: 0.0624 | Q21: in progress | R21: 0.312 | S21: 0.312 | U21: 16 | V21: Grow | W21: Organic | X21: 1. Grow profitably | Y21: Launch a New Business | Z21: Autonomous Driving Systems Unit | AA21: Launch dedicated business unit for advanced driver assistance systems (ADAS) and autonomous driving technology. High potential but uncertain returns as technology evolves rapidly. | AB21: 2 | AC21: 4 | AD21: 2 | AE21: 2 | AF21: 0 | AG21: -1000 | AH21: -233.81744 | AI21: 0.0624 | AJ21: 112 | AK21: low growth bad capital turnover but high margin | AL21: Dilutive | AS21: 800 | AT21: 0 | AU21: -1000 | AV21: 2 | AW21: 0.1 | AY21: 0 | AZ21: 0 | BA21: 0 | BB21: 0 | BD21: 0 | BE21: 0 | BF21: 0 | BG21: 0
C22: close to cost of capital: 0% growth, 6% EBIT | E22: 3 | F22: 2 | G22: 0.15 | H22: 0 | I22: 0.06 | K22: 2 | L22: 2 | M22: 2 | P22: 0.0936 | Q22: in progress | R22: 0.39 | S22: 0.39 | U22: 17 | V22: Grow | W22: Organic | X22: 3. Stay flexible | Y22: Expand Manufacturing Footprint | Z22: Diversified OEM Capacity Investment | AA22: Invest in flexible powertrain manufacturing capacity additions across existing facilities globally to serve multiple OEM customers. Spreads investment across GM, Ford, Honda, and BMW programs. Lower per-unit returns but diversified risk exposure. Requires more coordination but provides insurance against customer-specific disruptions. | AB22: 2 | AC22: 3 | AD22: 3 | AE22: 2 | AF22: 0 | AG22: -800 | AH22: 112.6476 | AI22: 0.0936 | AJ22: 160 | AK22: close to cost of capital: 0% growth, 6% EBIT | AL22: Accretive | AS22: 1600 | AT22: 0 | AU22: -800 | AV22: 2 | AW22: 0.06 | AY22: 0 | AZ22: 0 | BA22: 0 | BB22: 0 | BD22: 0 | BE22: 0 | BF22: 0 | BG22: 0
C23: accretive with ROIC 15% | E23: 4 | F23: 2 | G23: 0.2 | H23: 0.05 | I23: 0.11 | K23: 1.5 | L23: 1.5 | M23: 1.5 | P23: 0.21900992 | Q23: in progress | R23: 0.52 | S23: 0.52 | U23: 18 | V23: Grow | W23: M&A / Divestments | X23: 1. Grow profitably | Y23: Acquire a Business | Z23: Bolt-on Sensor Acquisition | AA23: Acquire small sensor technology company to enhance ADAS capabilities. Adds specialized engineering talent and IP. Integration risk exists but accelerates time-to-market. | AB23: 2 | AC23: 3 | AD23: 2 | AE23: 1 | AF23: 0 | AG23: -3941.5797 | AH23: 6.5086523 | AI23: 0.081988325 | AJ23: 483.153 | AK23: M&A (1 for Divestments) | AL23: Accretive | AS23: 2000 | AT23: 0.1 | AU23: 0 | AV23: 0 | AW23: 0.11 | AY23: 0 | AZ23: 0 | BA23: 1 | BB23: 0 | BD23: 0 | BE23: 0 | BF23: 0 | BG23: 0
C24: accretive with ROIC 20% | E24: 5 | F24: 2.5 | G24: 0.2 | H24: 0.03 | I24: 0.11 | K24: 1 | L24: 1 | M24: 1 | P24: 0.24866429 | R24: 0.78 | S24: 0.78 | U24: 19 | V24: Grow | W24: Organic | X24: 1. Grow profitably | Y24: Platform-Level Technology Bets | Z24: Software-Defined Vehicle Platform | AA24: Make a targeted technology bet on modular, software-defined vehicle architectures, reflecting OEM demand for faster feature deployment, lower lifecycle cost, and vendor-agnostic platforms. | AB24: 2 | AC24: 5 | AD24: 2 | AE24: 2 | AF24: 0 | AG24: -1000 | AH24: -233.81744 | AI24: 0.0624 | AJ24: 112 | AK24: low growth bad capital turnover but high margin | AL24: Dilutive | AS24: 800 | AT24: 0 | AU24: -1000 | AV24: 2 | AW24: 0.1 | AY24: 0 | AZ24: 0 | BA24: 0 | BB24: 0 | BD24: 0 | BE24: 0 | BF24: 0 | BG24: 0
E25: step | K25: 0.5 | L25: 0.5 | M25: 0.5 | P25: Note: ROIC can be slighly different due to short-term growth | U25: 20 | V25: Grow | W25: Organic | X25: 3. Stay flexible | Y25: Expand Manufacturing Footprint | Z25: European Advanced Assembly Facility | AA25: Build dedicated advanced vehicle assembly plant in Eastern Europe. Positions for European regulatory requirements and next-gen vehicle platforms. Significant investment with long payback period. | AB25: 2 | AC25: 4 | AD25: 1 | AE25: 3 | AF25: 0 | AG25: -1000 | AH25: -205.98667 | AI25: 0.067817533 | AJ25: 156.502 | AK25: high growth low margin | AL25: Dilutive | AS25: 1500 | AT25: 0.03 | AU25: -1000 | AV25: 3 | AW25: 0.05 | AY25: 0 | AZ25: 0 | BA25: 0 | BB25: 0 | BD25: 0 | BE25: 0 | BF25: 0 | BG25: 0
U26: 21 | V26: Optimize | W26: COGS savings | X26: 1. Grow profitably | Y26: Enterprise Digital Transformation | Z26: Advanced Analytics Platform | AA26: Deploy enterprise analytics platform to improve decision-making across operations. Predictive insights for demand planning, quality, and maintenance. | AB26: 2 | AC26: 2 | AD26: 1 | AE26: 1 | AF26: 0 | AG26: -120 | AH26: 277.61555 | AI26: 0.26 | AJ26: 40 | AL26: Accretive | AS26: 0 | AT26: 0 | AU26: 0 | AV26: 0 | AY26: 3 | AZ26: 0 | BA26: 1 | BB26: 40 | BD26: 0 | BE26: 0 | BF26: 0 | BG26: 0
G27: M&A / Divestments | H27: M&A / Divestments | U27: 22 | V27: Optimize | W27: Manufacturing OH savings | X27: 2. Cash is king | Y27: Factory of the Future | Z27: Automation Expansion Program | AA27: Expand robotic automation across manufacturing facilities. Higher upfront cost but significant labor cost reduction and quality improvement. | AB27: 2 | AC27: 4 | AD27: 1 | AE27: 1 | AF27: 0 | AG27: -360 | AH27: 832.84666 | AI27: 0.26 | AJ27: 120 | AL27: Accretive | AS27: 0 | AT27: 0 | AU27: 0 | AV27: 0 | AY27: 0 | AZ27: -360 | BA27: 1 | BB27: 120 | BD27: 0 | BE27: 0 | BF27: 0 | BG27: 0
F28: Synergies | G28: Gross Margin (only COGS impact) | H28: 5-year growth | U28: 23 | V28: Optimize | W28: COGS savings | X28: 1. Grow profitably | Y28: Select Group Transformation | Z28: Underperforming Division Turnaround | AA28: Comprehensive operational improvement program for underperforming business unit. New leadership, process redesign, and targeted investments. | AB28: 2 | AC28: 3 | AD28: 1 | AE28: 1 | AF28: 0 | AG28: -240 | AH28: 555.23111 | AI28: 0.26 | AJ28: 80 | AL28: Accretive | AS28: 0 | AT28: 0 | AU28: 0 | AV28: 0 | AY28: 3 | AZ28: 0 | BA28: 1 | BB28: 80 | BD28: 0 | BE28: 0 | BF28: 0 | BG28: 0
F29: as % of Acquired Revenue | G29: % | H29: CAGR | U29: 24 | V29: Optimize | W29: COGS savings | X29: 1. Grow profitably | Y29: Global Supply Chain Redesign | Z29: Logistics Network Optimization | AA29: Redesign global logistics network to reduce transportation costs and improve delivery times. Consolidate warehouses and optimize routes. | AB29: 2 | AC29: 3 | AD29: 1 | AE29: 1 | AF29: 0 | AG29: -240 | AH29: 555.23111 | AI29: 0.26 | AJ29: 80 | AL29: Accretive | AS29: 0 | AT29: 0 | AU29: 0 | AV29: 0 | AY29: 3 | AZ29: 0 | BA29: 1 | BB29: 80 | BD29: 0 | BE29: 0 | BF29: 0 | BG29: 0
E30: 1 | G30: 0.14 | H30: 0 | I30: Divestment | U30: 25 | V30: Optimize | W30: SGA savings | X30: 1. Grow profitably | Y30: SG&A Optimization | Z30: Procurement Excellence Program | AA30: Implement strategic sourcing and supplier management program. Leverage scale for better pricing and terms on indirect spend. | AB30: 2 | AC30: 2 | AD30: 1 | AE30: 1 | AF30: 0 | AG30: -120 | AH30: 277.61555 | AI30: 0.26 | AJ30: 40 | AL30: Accretive | AS30: 0 | AT30: 0 | AU30: 0 | AV30: 0 | AY30: 3 | AZ30: 0 | BA30: 1 | BB30: 40 | BD30: 0 | BE30: 0 | BF30: 0 | BG30: 0
E31: 2 | F31: 0.03 | G31: 0.2 | H31: 0.1 | I31: Acquisition | U31: 26 | V31: Sustain | W31: SGA savings | X31: 1. Grow profitably | Y31: Talent & Leadership Upskilling | Z31: Leadership Development Program | AA31: Comprehensive leadership development for high-potential managers. Builds succession pipeline and organizational capability. Long-term investment in human capital. | AB31: 2 | AC31: 2 | AD31: 1 | AE31: 1 | AF31: 0 | AG31: -120 | AH31: 277.61555 | AI31: 0.26 | AJ31: 40 | AL31: Accretive | AS31: 0 | AT31: 0 | AU31: 0 | AV31: 0 | AY31: 3 | AZ31: 0 | BA31: 0 | BB31: 0 | BD31: 3 | BE31: 0 | BF31: 1 | BG31: 40
E32: 3 | F32: 0.03 | G32: 0.2 | H32: 0.1 | I32: Acquisition | U32: 27 | V32: Sustain | W32: Sustain Topline | X32: 1. Grow profitably | Y32: Risk & Compliance Upgrade | Z32: Quality Management System Upgrade | AA32: Upgrade quality management systems to meet evolving OEM requirements. Essential for maintaining key customer relationships. Prevents costly quality escapes. | AB32: 2 | AC32: 2 | AD32: 1 | AE32: 1 | AF32: 0 | AG32: -80 | AH32: -68.587106 | AI32: 0 | AJ32: 0 | AL32: Accretive | AS32: 0 | AT32: 0 | AU32: 0 | AV32: 0 | AY32: 0 | AZ32: 0 | BA32: 0 | BB32: 0 | BD32: 0 | BE32: -80 | BF32: 1 | BG32: 0 | BH32: No incremental cash flow created Avoid losing business-as-usual revenue -0.1% y-o-y
E33: 4 | F33: 0.03 | G33: 0.2 | H33: 0.1 | I33: Acquisition | U33: 28 | V33: Sustain | W33: COGS savings | X33: 1. Grow profitably | Y33: Capital allocation strategy (maintenance) | Z33: IT Infrastructure Modernization | AA33: Update core IT systems and infrastructure. Addresses technical debt and security vulnerabilities. Foundational investment enabling future digital initiatives. | AB33: 2 | AC33: 2 | AD33: 1 | AE33: 1 | AF33: 0 | AG33: -120 | AH33: 277.61555 | AI33: 0.26 | AJ33: 40 | AL33: Accretive | AS33: 0 | AT33: 0 | AU33: 0 | AV33: 0 | AY33: 3 | AZ33: 0 | BA33: 0 | BB33: 0 | BD33: 3 | BE33: 0 | BF33: 1 | BG33: 40
E34: 5 | F34: 0.03 | G34: 0.2 | H34: 0.1 | I34: Acquisition | U34: 29 | V34: Sustain | W34: Sustain Topline | X34: 3. Stay flexible | Y34: Risk & Compliance Upgrade | Z34: Health & Safety Investment | AA34: Enhanced workplace safety equipment and training programs. Essential for employee welfare and regulatory compliance. Reduces accident-related costs. | AB34: 2 | AC34: 1 | AD34: 1 | AE34: 1 | AF34: 0 | AG34: -40 | AH34: -34.293553 | AI34: 0 | AJ34: 0 | AL34: Accretive | AS34: 0 | AT34: 0 | AU34: 0 | AV34: 0 | AY34: 0 | AZ34: 0 | BA34: 0 | BB34: 0 | BD34: 0 | BE34: -40 | BF34: 1 | BG34: 0 | BH34: No incremental cash flow created Avoid losing business-as-usual revenue -0.1% y-o-y
U35: 30 | V35: Sustain | W35: COGS savings | X35: 1. Grow profitably | Y35: Portfolio management (maintenance) | Z35: Supplier Relationship Investment | AA35: Strengthen relationships with strategic suppliers through joint development and long-term agreements. Improves supply security and preferential allocation. | AB35: 2 | AC35: 2 | AD35: 1 | AE35: 1 | AF35: 0 | AG35: -120 | AH35: 277.61555 | AI35: 0.26 | AJ35: 40 | AL35: Dilutive | AS35: 0 | AT35: 0 | AU35: 0 | AV35: 0 | AY35: 3 | AZ35: 0 | BA35: 0 | BB35: 0 | BD35: 3 | BE35: 0 | BF35: 1 | BG35: 40
U36: 31 | V36: Grow | W36: Organic | X36: 1. Grow profitably | Y36: Expand Manufacturing Footprint | Z36: North America Advanced Component Hub | AA36: Consolidate advanced component manufacturing across business units into a single, dedicated cross-group facility, capturing scale efficiencies and capability depth while requiring a significant fixed-asset commitment amid uncertain market demand. | AB36: 3 | AC36: 4 | AD36: 1 | AE36: 1 | AF36: 0 | AG36: -1000 | AH36: -155.9752 | AI36: 0.067817533 | AJ36: 156.502 | AK36: high growth low margin | AL36: Dilutive | AS36: 1500 | AT36: 0.03 | AU36: -1000 | AV36: 1 | AW36: 0.05 | AY36: 0 | AZ36: 0 | BA36: 0 | BB36: 0 | BD36: 0 | BE36: 0 | BF36: 0 | BG36: 0
U37: 32 | V37: Grow | W37: Organic | X37: 1. Grow profitably | Y37: JV / Strategic Partnership | Z37: Chinese OEM Partnership | AA37: Strategic partnership with leading Chinese automotive manufacturer. Access to largest automotive growth market but geopolitical and IP concerns. High reward potential with elevated risk. | AB37: 3 | AC37: 4 | AD37: 1 | AE37: 1 | AF37: 0 | AG37: -1000 | AH37: -155.9752 | AI37: 0.067817533 | AJ37: 156.502 | AL37: Accretive | AS37: 1500 | AT37: 0.03 | AU37: -1000 | AV37: 1 | AW37: 0.05 | AY37: 0 | AZ37: 0 | BA37: 0 | BB37: 0 | BD37: 0 | BE37: 0 | BF37: 0 | BG37: 0
E38: General assumptions | U38: 33 | V38: Grow | W38: M&A / Divestments | X38: 1. Grow profitably | Y38: Acquire a Business | Z38: Distressed Competitor Acquisition | AA38: Opportunity to acquire struggling competitor at attractive valuation. Significant capacity and customer relationships, but integration complexity and some legacy issues. | AB38: 3 | AC38: 5 | AD38: 2 | AE38: 1 | AF38: 0 | AG38: -15795.29 | AH38: 45.266863 | AI38: 0.081837943 | AJ38: 1932.612 | AK38: low growth bad capital turnover but high margin | AL38: Dilutive | AS38: 8000 | AT38: 0.1 | AU38: 0 | AV38: 0 | AW38: 0.11 | AY38: 0 | AZ38: 0 | BA38: 1 | BB38: 0 | BD38: 0 | BE38: 0 | BF38: 0 | BG38: 0
E39: Base Revenue | F39: 40000 | G39: Actual revenue rounded | K39: Inorganic | U39: 34 | V39: Grow | W39: Organic | X39: 1. Grow profitably | Y39: Scale R&D for Next-Gen Portfolio | Z39: Solid-State Battery Research | AA39: Invest in next-generation solid-state battery technology research. Could leapfrog current technology but commercialization timeline uncertain. | AB39: 3 | AC39: 4 | AD39: 1 | AE39: 1 | AF39: 0 | AG39: -1000 | AH39: -155.9752 | AI39: 0.067817533 | AJ39: 156.502 | AK39: high growth low margin | AL39: Dilutive | AS39: 1500 | AT39: 0.03 | AU39: -1000 | AV39: 1 | AW39: 0.05 | AY39: 0 | AZ39: 0 | BA39: 0 | BB39: 0 | BD39: 0 | BE39: 0 | BF39: 0 | BG39: 0
E40: Capex maintenance | F40: 0.04 | G40: In line with peer average | U40: 35 | V40: Grow | W40: Organic | X40: 1. Grow profitably | Y40: Revenue Diversification | Z40: Expand Beyond OEMs into Non-Traditional Customers | AA40: Pursue revenue opportunities with non-OEM customers (e.g., Amazon, fleet operators, mobility platforms) by adapting Magna’s manufacturing and engineering capabilities to adjacent use cases. | AB40: 3 | AC40: 2 | AD40: 1 | AE40: 1 | AF40: 0 | AG40: -600 | AH40: -93.585119 | AI40: 0.067817533 | AJ40: 93.9012 | AK40: high growth low margin | AL40: Accretive | AS40: 900 | AT40: 0.03 | AU40: -600 | AV40: 1 | AW40: 0.05 | AY40: 0 | AZ40: 0 | BA40: 0 | BB40: 0 | BD40: 0 | BE40: 0 | BF40: 0 | BG40: 0
E41: Taxes | F41: 0.22 | U41: 36 | V41: Optimize | W41: M&A / Divestments | X41: 2. Cash is king | Y41: Divest Group | Z41: Non-Core Division Divestiture | AA41: Divest underperforming non-core business unit. Generates cash and allows focus on strategic priorities. May face valuation pressure in current market. | AB41: 3 | AC41: 1 | AD41: 1 | AE41: 1 | AF41: 0 | AG41: 598.65368 | AH41: -150.92639 | AI41: 0.10022489 | AJ41: -108 | AK41: M&A (1 for Divestments) | AL41: Accretive | AS41: -1200 | AT41: 0 | AU41: 0 | AV41: 0 | AW41: 0.05 | AY41: 0 | AZ41: 0 | BA41: 1 | BB41: 0 | BD41: 0 | BE41: 0 | BF41: 0 | BG41: 0
E42: WACC | F42: 0.08 | G42: Based on a 9.3% cost of equity, a 4.9% pre-tax cost of debt (A- rating), and a 75/25 capital structure | U42: 37 | V42: Optimize | W42: COGS savings | X42: 3. Stay flexible | Y42: Program Governance | Z42: Bypass Standard Launch Gates to Meet SOP Deadline | AA42: Streamline or bypass select internal approval and validation steps to meet OEM SOP deadlines and avoid penalties, accepting higher rework risk in exchange for schedule adherence and cost savings. | AB42: 3 | AC42: 3 | AD42: 1 | AE42: 1 | AF42: 0 | AG42: -240 | AH42: 520.93755 | AI42: 0.26 | AJ42: 80 | AL42: Dilutive | AS42: 0 | AT42: 0 | AU42: 0 | AV42: 0 | AY42: 3 | AZ42: 0 | BA42: 1 | BB42: 80 | BD42: 0 | BE42: 0 | BF42: 0 | BG42: 0
...

Sheet Output
P2: Ungroup to see Decisions consolidated | AU2: Ungroup to see Intermediate calculations | BK2: Ungroup to see No-Decision Simulation
B4: Simplified financials
B5: Currency: USD Millions
B7: Legend
B8: Calculations and same-sheet references
B9: Formula includes links to other sheets within same file | AG9: Turn On Round | AI9: 1 | AJ9: 1 | AK9: 1 | AL9: 1 | AM9: 1
B10: Assumption/input | AV10: Continuing Value (growth) | AW10: =BG60 -> 0.02 | AY10: WACC | AZ10: =Decisions!F42 -> 0.08
B12: Simulation - Results | Q12: Simulations - Decisions | AG12: Simulation - Intermediate | AH12: Includes the impact of selected Sustain Revenue Decisions. To see No Decision Simulation refer to BL:BX | AV12: Business-As-Usual | BL12: Simulation - No Decisions
C14: =AH14 -> 2025 | D14: =AI14 -> 2026 | E14: =AJ14 -> 2027 | F14: =AK14 -> 2028 | G14: =AL14 -> 2029 | H14: =AM14 -> 2030 | I14: =AN14 -> 2031 | J14: =AO14 -> 2032 | ... N14: =AS14 -> Long-Term | O14: Total | Q14: Consolidated Decision FCF | R14: =AH14 -> 2025 | S14: =AI14 -> 2026 | T14: =AJ14 -> 2027 | U14: =AK14 -> 2028 | V14: =AL14 -> 2029 | W14: =AM14 -> 2030 | X14: =AN14 -> 2031 | Y14: =AO14 -> 2032 | ... AC14: =AS14 -> Long-Term | AD14: Total | AH14: =AW14 -> 2025 | AI14: =AX14 -> 2026 | AJ14: =AY14 -> 2027 | AK14: =AZ14 -> 2028 | AL14: =BA14 -> 2029 | AM14: =BB14 -> 2030 | AN14: =BC14 -> 2031 | AO14: =BD14 -> 2032 | ... AS14: =BH14 -> Long-Term | AT14: Total | AW14: 2025 | AX14: =AW14+1 -> 2026 | AY14: =AX14+1 -> 2027 | AZ14: =AY14+1 -> 2028 | BA14: =AZ14+1 -> 2029 | BB14: =BA14+1 -> 2030 | BC14: =BB14+1 -> 2031 | BD14: =BC14+1 -> 2032 | BE14: =BD14+1 -> 2033 | ... BG14: =BF14+1 -> 2035 | BH14: Long-Term | BM14: =AH14 -> 2025 | BN14: =AI14 -> 2026 | BO14: =AJ14 -> 2027 | BP14: =AK14 -> 2028 | BQ14: =AL14 -> 2029 | BR14: =AM14 -> 2030 | BS14: =AN14 -> 2031 | BT14: =AO14 -> 2032 | ... BX14: =AS14 -> Long-Term
B15: Investment | C15: =R15+AH15 -> 0 | D15: =S15+AI15 -> 0 | E15: =T15+AJ15 -> 0 | F15: =U15+AK15 -> 0 | G15: =V15+AL15 -> 0 | H15: =W15+AM15 -> 0 | I15: =X15+AN15 -> 0 | J15: =Y15+AO15 -> 0 | ... M15: =AB15+AR15 -> 0 | O15: =SUM(D15:M15) -> 0 | Q15: Investment | S15: =Decisions!BG87 -> 0 | T15: =Decisions!BH87 -> 0 | U15: =Decisions!BI87 -> 0 | V15: =Decisions!BJ87 -> 0 | W15: =Decisions!BK87 -> 0 | X15: =Decisions!BL87 -> 0 | Y15: =Decisions!BM87 -> 0 | Z15: =Decisions!BN87 -> 0 | ... AB15: =Decisions!BP87 -> 0 | AD15: =SUM(S15:AB15) -> 0 | AG15: Investment | AV15: Investment | BL15: Investment
B16: Implementation Cost | C16: =R16+AH16 -> 0 | D16: =S16+AI16 -> 0 | E16: =T16+AJ16 -> 0 | F16: =U16+AK16 -> 0 | G16: =V16+AL16 -> 0 | H16: =W16+AM16 -> 0 | I16: =X16+AN16 -> 0 | J16: =Y16+AO16 -> 0 | ... M16: =AB16+AR16 -> 0 | Q16: Implementation Cost | S16: =Decisions!BG88 -> 0 | T16: =Decisions!BH88 -> 0 | U16: =Decisions!BI88 -> 0 | V16: =Decisions!BJ88 -> 0 | W16: =Decisions!BK88 -> 0 | X16: =Decisions!BL88 -> 0 | Y16: =Decisions!BM88 -> 0 | Z16: =Decisions!BN88 -> 0 | ... AB16: =Decisions!BP88 -> 0 | AD16: =SUM(S16:AB16) -> 0 | AG16: Implementation Cost | AV16: Implementation Cost | BL16: Implementation Cost
B17: Acquision | C17: =R17+AH17 -> 0 | D17: =S17+AI17 -> 0 | E17: =T17+AJ17 -> 0 | F17: =U17+AK17 -> 0 | G17: =V17+AL17 -> -13050.403 | H17: =W17+AM17 -> 0 | I17: =X17+AN17 -> 0 | J17: =Y17+AO17 -> 0 | ... M17: =AB17+AR17 -> 0 | Q17: Acquision | S17: =Decisions!BG89 -> 0 | T17: =Decisions!BH89 -> 0 | U17: =Decisions!BI89 -> 0 | V17: =Decisions!BJ89 -> -13050.403 | W17: =Decisions!BK89 -> 0 | X17: =Decisions!BL89 -> 0 | Y17: =Decisions!BM89 -> 0 | Z17: =Decisions!BN89 -> 0 | ... AB17: =Decisions!BP89 -> 0 | AD17: =SUM(S17:AB17) -> -13050.403 | AG17: Acquision | AV17: Acquision | BL17: Acquision
B18: Premium | Q18: Premium | S18: =Decisions!BG90 -> 0 | T18: =Decisions!BH90 -> 0 | U18: =Decisions!BI90 -> 0 | V18: =Decisions!BJ90 -> 0 | W18: =Decisions!BK90 -> 0 | X18: =Decisions!BL90 -> 0 | Y18: =Decisions!BM90 -> 0 | Z18: =Decisions!BN90 -> 0 | ... AB18: =Decisions!BP90 -> 0 | AD18: =SUM(S18:AB18) -> 0 | AG18: Premium | AV18: Premium
B19: Investments Total | C19: =SUM(C15:C17) -> 0 | D19: =SUM(D15:D17) -> 0 | E19: =SUM(E15:E17) -> 0 | F19: =SUM(F15:F17) -> 0 | G19: =SUM(G15:G17) -> -13050.403 | H19: =SUM(H15:H17) -> 0 | I19: =SUM(I15:I17) -> 0 | J19: =SUM(J15:J17) -> 0 | ... M19: =SUM(M15:M17) -> 0 | O19: =SUM(D19:M19) -> -13050.403 | Q19: Investments Total | S19: =SUM(S15:S17) -> 0 | T19: =SUM(T15:T17) -> 0 | U19: =SUM(U15:U17) -> 0 | V19: =SUM(V15:V17) -> -13050.403 | W19: =SUM(W15:W17) -> 0 | X19: =SUM(X15:X17) -> 0 | Y19: =SUM(Y15:Y17) -> 0 | Z19: =SUM(Z15:Z17) -> 0 | ... AB19: =SUM(AB15:AB17) -> 0 | AD19: =SUM(S19:AB19) -> -13050.403 | AG19: Investments Total | AV19: Investments Total | BL19: Investments Total
B20: Revenue | C20: =R20+AH20 -> 42836 | D20: =S20+AI20 -> 42836 | E20: =T20+AJ20 -> 43692.72 | F20: =U20+AK20 -> 44435.496 | G20: =V20+AL20 -> 45102.029 | H20: =W20+AM20 -> 45930.806 | I20: =X20+AN20 -> 52341.112 | J20: =Y20+AO20 -> 52562.818 | ... M20: =AB20+AR20 -> 53234.608 | Q20: Revenue | S20: =Decisions!BG92 -> 0 | T20: =Decisions!BH92 -> 0 | U20: =Decisions!BI92 -> 0 | V20: =Decisions!BJ92 -> 0 | W20: =Decisions!BK92 -> 8000 | X20: =Decisions!BL92 -> 8000 | Y20: =Decisions!BM92 -> 8000 | Z20: =Decisions!BN92 -> 8000 | ... AB20: =Decisions!BP92 -> 8000 | AG20: Revenue | AH20: =AW22 -> 42836 | AI20: =AH20+AH21 -> 42836 | AJ20: =AI20+AI21 -> 43692.72 | AK20: =AJ20+AJ21 -> 44435.496 | AL20: =AK20+AK21 -> 45102.029 | AM20: =AL20+AL21 -> 37930.806 | AN20: =AM20+AM21 -> 44341.112 | AO20: =AN20+AN21 -> 44562.818 | AP20: =AO20+AO21 -> 44785.632 | ... AR20: =AQ20+AQ21 -> 45234.608 | AV20: Revenue | BL20: Revenue | BM20: =AW22 -> 42836 | BN20: =BM20*(1+BN60) -> 43692.72 | BO20: =BN20+BN21 -> 43692.72 | BP20: =BO20+BO21 -> 44435.496 | BQ20: =BP20+BP21 -> 45102.029 | BR20: =BQ20+BQ21 -> 37930.806 | BS20: =BR20+BR21 -> 44341.112 | BT20: =BS20+BS21 -> 44562.818 | BU20: =BT20+BT21 -> 44785.632 | BV20: =BU20+BU21 -> 45009.56 | BW20: =BV20+BV21 -> 45234.608
B21: Growth | C21: =R21+AH21 -> 0 | D21: =S21+AI21 -> 856.72 | E21: =T21+AJ21 -> 742.77624 | F21: =U21+AK21 -> 666.53244 | G21: =V21+AL21 -> -7171.2226 | H21: =W21+AM21 -> 6410.3062 | I21: =X21+AN21 -> 1021.7056 | J21: =Y21+AO21 -> 1902.8141 | ... M21: =AB21+AR21 -> 5110.253 | Q21: Growth | S21: =Decisions!BG93 -> 0 | T21: =Decisions!BH93 -> 0 | U21: =Decisions!BI93 -> 0 | V21: =Decisions!BJ93 -> 0 | W21: =Decisions!BK93 -> 0 | X21: =Decisions!BL93 -> 800 | Y21: =Decisions!BM93 -> 1680 | Z21: =Decisions!BN93 -> 2648 | ... AB21: =Decisions!BP93 -> 4884.08 | AG21: Growth | AI21: =AI60*AI20 -> 856.72 | AJ21: =AJ60*AJ20 -> 742.77624 | AK21: =AK60*AK20 -> 666.53244 | AL21: =AL60*AL20 -> -7171.2226 | AM21: =AM60*AM20 -> 6410.3062 | AN21: =AN60*AN20 -> 221.70556 | AO21: =AO60*AO20 -> 222.81409 | AP21: =AP60*AP20 -> 223.92816 | ... AR21: =AR60*AR20 -> 226.17304 | AV21: Growth | BL21: Growth | BO21: =BO60*BO20 -> 742.77624 | BP21: =BP60*BP20 -> 666.53244 | BQ21: =BQ60*BQ20 -> -7171.2226 | BR21: =BR60*BR20 -> 6410.3062 | BS21: =BS60*BS20 -> 221.70556 | BT21: =BT60*BT20 -> 222.81409 | BU21: =BU60*BU20 -> 223.92816 | BV21: =BV60*BV20 -> 225.0478 | BW21: =BW60*BW20 -> 226.17304
B22: Revenue Total | C22: =C21+C20 -> 42836 | D22: =D21+D20 -> 43692.72 | E22: =E21+E20 -> 44435.496 | F22: =F21+F20 -> 45102.029 | G22: =G21+G20 -> 37930.806 | H22: =H21+H20 -> 52341.112 | I22: =I21+I20 -> 53362.818 | J22: =J21+J20 -> 54465.632 | ... M22: =M21+M20 -> 58344.861 | Q22: Revenue Total | S22: =S21+S20 -> 0 | T22: =T21+T20 -> 0 | U22: =U21+U20 -> 0 | V22: =V21+V20 -> 0 | W22: =W21+W20 -> 8000 | X22: =X21+X20 -> 8800 | Y22: =Y21+Y20 -> 9680 | Z22: =Z21+Z20 -> 10648 | ... AB22: =AB21+AB20 -> 12884.08 | AG22: Revenue Total | AH22: =AH21+AH20 -> 42836 | AI22: =AI21+AI20 -> 43692.72 | AJ22: =AJ21+AJ20 -> 44435.496 | AK22: =AK21+AK20 -> 45102.029 | AL22: =AL21+AL20 -> 37930.806 | AM22: =AM21+AM20 -> 44341.112 | AN22: =AN21+AN20 -> 44562.818 | AO22: =AO21+AO20 -> 44785.632 | ... AS22: =AS21+AS20 -> 0 | AV22: Revenue Total | AW22: =Baseline!C5 -> 42836 | AX22: =AW22*(1+AX60) -> 43692.72 | AY22: =AX22*(1+AY60) -> 44566.574 | AZ22: =AY22*(1+AZ60) -> 45457.906 | BA22: =AZ22*(1+BA60) -> 46367.064 | BB22: =BA22*(1+BB60) -> 47294.405 | BC22: =BB22*(1+BC60) -> 48240.293 | BD22: =BC22*(1+BD60) -> 49205.099 | BE22: =BD22*(1+BE60) -> 50189.201 | ... BG22: =BF22*(1+BG60) -> 52216.845 | BH22: =BH21+BH20 -> 0 | BL22: Revenue Total | BM22: =BM21+BM20 -> 42836 | BN22: =BN21+BN20 -> 43692.72 | BO22: =BO21+BO20 -> 44435.496 | BP22: =BP21+BP20 -> 45102.029 | BQ22: =BQ21+BQ20 -> 37930.806 | BR22: =BR21+BR20 -> 44341.112 | BS22: =BS21+BS20 -> 44562.818 | BT22: =BT21+BT20 -> 44785.632 | ... BW22: =BW21+BW20 -> 45460.781
B23: COGS | C23: =R23+AH23 -> -37037 | D23: =S23+AI23 -> -37777.74 | E23: =T23+AJ23 -> -38419.962 | F23: =U23+AK23 -> -39221.771 | G23: =V23+AL23 -> -32985.51 | H23: =W23+AM23 -> -44960.061 | I23: =X23+AN23 -> -45792.861 | J23: =Y23+AO23 -> -46690.625 | ... M23: =AB23+AR23 -> -49841.014 | Q23: COGS | S23: =Decisions!BG95 -> 0 | T23: =Decisions!BH95 -> 0 | U23: =Decisions!BI95 -> 0 | V23: =Decisions!BJ95 -> 0 | W23: =Decisions!BK95 -> -6400 | X23: =Decisions!BL95 -> -7040 | Y23: =Decisions!BM95 -> -7744 | Z23: =Decisions!BN95 -> -8518.4 | ... AB23: =Decisions!BP95 -> -10307.264 | AG23: COGS | AH23: =AW23 -> -37037 | AI23: =-AI63*AI22 -> -37777.74 | AJ23: =-AJ63*AJ22 -> -38419.962 | AK23: =-AK63*AK22 -> -39221.771 | AL23: =-AL63*AL22 -> -32985.51 | AM23: =-AM63*AM22 -> -38560.061 | AN23: =-AN63*AN22 -> -38752.861 | AO23: =-AO63*AO22 -> -38946.625 | AP23: =-AP63*AP22 -> -39141.358 | ... AR23: =-AR63*AR22 -> -39533.75 | AV23: COGS | AW23: =Baseline!C6 -> -37037 | AX23: =-AX63*AX22 -> -37777.74 | AY23: =-AY63*AY22 -> -38533.295 | AZ23: =-AZ63*AZ22 -> -39303.961 | BA23: =-BA63*BA22 -> -40090.04 | BB23: =-BB63*BB22 -> -40891.841 | BC23: =-BC63*BC22 -> -41709.678 | BD23: =-BD63*BD22 -> -42543.871 | BE23: =-BE63*BE22 -> -43394.748 | ... BG23: =-BG63*BG22 -> -45147.896 | BL23: COGS | BM23: =AW23 -> -37037 | BN23: =-BN63*BN22 -> -37777.74 | BO23: =-BO63*BO22 -> -38419.962 | BP23: =-BP63*BP22 -> -39221.771 | BQ23: =-BQ63*BQ22 -> -32985.51 | BR23: =-BR63*BR22 -> -38560.061 | BS23: =-BS63*BS22 -> -38752.861 | BT23: =-BT63*BT22 -> -38946.625 | BU23: =-BU63*BU22 -> -39141.358 | ... BW23: =-BW63*BW22 -> -39533.75
B24: SG&A | C24: =R24+AH24 -> -2061 | D24: =S24+AI24 -> -2102.22 | E24: =T24+AJ24 -> -2144.2644 | F24: =U24+AK24 -> -2187.1497 | G24: =V24+AL24 -> -2230.8927 | H24: =W24+AM24 -> -2675.5105 | I24: =X24+AN24 -> -2761.0207 | J24: =Y24+AO24 -> -2851.4412 | ... M24: =AB24+AR24 -> -3156.5515 | Q24: SG&A | S24: =Decisions!BG96 -> 0 | T24: =Decisions!BH96 -> 0 | U24: =Decisions!BI96 -> 0 | V24: =Decisions!BJ96 -> 0 | W24: =Decisions!BK96 -> -400 | X24: =Decisions!BL96 -> -440 | Y24: =Decisions!BM96 -> -484 | Z24: =Decisions!BN96 -> -532.4 | ... AB24: =Decisions!BP96 -> -644.204 | AG24: SG&A | AH24: =AW24 -> -2061 | AI24: =(1+AI65)*AH24 -> -2102.22 | AJ24: =(1+AJ65)*AI24 -> -2144.2644 | AK24: =(1+AK65)*AJ24 -> -2187.1497 | AL24: =(1+AL65)*AK24 -> -2230.8927 | AM24: =(1+AM65)*AL24 -> -2275.5105 | AN24: =(1+AN65)*AM24 -> -2321.0207 | AO24: =(1+AO65)*AN24 -> -2367.4412 | AP24: =(1+AP65)*AO24 -> -2414.79 | ... AR24: =(1+AR65)*AQ24 -> -2512.3475 | AV24: SG&A | AW24: =Baseline!C7 -> -2061 | AX24: =-AX64*AX22 -> -2102.22 | AY24: =-AY64*AY22 -> -2144.2644 | AZ24: =-AZ64*AZ22 -> -2187.1497 | BA24: =-BA64*BA22 -> -2230.8927 | BB24: =-BB64*BB22 -> -2275.5105 | BC24: =-BC64*BC22 -> -2321.0207 | BD24: =-BD64*BD22 -> -2367.4412 | BE24: =-BE64*BE22 -> -2414.79 | ... BG24: =-BG64*BG22 -> -2512.3475 | BL24: SG&A | BM24: =AW24 -> -2061 | BN24: =(1+BN65)*BM24 -> -2102.22 | BO24: =(1+BO65)*BN24 -> -2144.2644 | BP24: =(1+BP65)*BO24 -> -2187.1497 | BQ24: =(1+BQ65)*BP24 -> -2230.8927 | BR24: =(1+BR65)*BQ24 -> -2275.5105 | BS24: =(1+BS65)*BR24 -> -2321.0207 | BT24: =(1+BT65)*BS24 -> -2367.4412 | BU24: =(1+BU65)*BT24 -> -2414.79 | ... BW24: =(1+BW65)*BV24 -> -2512.3475
B25: EBITDA | C25: =SUM(C22,C23,C24) -> 3738 | D25: =SUM(D22,D23,D24) -> 3812.76 | E25: =SUM(E22,E23,E24) -> 3871.2703 | F25: =SUM(F22,F23,F24) -> 3693.1078 | G25: =SUM(G22,G23,G24) -> 2714.4039 | H25: =SUM(H22,H23,H24) -> 4705.5412 | I25: =SUM(I22,I23,I24) -> 4808.9362 | J25: =SUM(J22,J23,J24) -> 4923.5656 | ... M25: =SUM(M22,M23,M24) -> 5347.295 | Q25: EBITDA | S25: =SUM(S22,S23,S24) -> 0 | T25: =SUM(T22,T23,T24) -> 0 | U25: =SUM(U22,U23,U24) -> 0 | V25: =SUM(V22,V23,V24) -> 0 | W25: =SUM(W22,W23,W24) -> 1200 | X25: =SUM(X22,X23,X24) -> 1320 | Y25: =SUM(Y22,Y23,Y24) -> 1452 | Z25: =SUM(Z22,Z23,Z24) -> 1597.2 | ... AB25: =SUM(AB22,AB23,AB24) -> 1932.612 | AG25: EBITDA | AH25: =SUM(AH22,AH23,AH24) -> 3738 | AI25: =SUM(AI22,AI23,AI24) -> 3812.76 | AJ25: =SUM(AJ22,AJ23,AJ24) -> 3871.2703 | AK25: =SUM(AK22,AK23,AK24) -> 3693.1078 | AL25: =SUM(AL22,AL23,AL24) -> 2714.4039 | AM25: =SUM(AM22,AM23,AM24) -> 3505.5412 | AN25: =SUM(AN22,AN23,AN24) -> 3488.9362 | AO25: =SUM(AO22,AO23,AO24) -> 3471.5656 | ... AR25: =SUM(AR22,AR23,AR24) -> 3414.683 | AV25: EBITDA | AW25: =SUM(AW22,AW23,AW24) -> 3738 | AX25: =SUM(AX22,AX23,AX24) -> 3812.76 | AY25: =SUM(AY22,AY23,AY24) -> 3889.0152 | AZ25: =SUM(AZ22,AZ23,AZ24) -> 3966.7955 | BA25: =SUM(BA22,BA23,BA24) -> 4046.1314 | BB25: =SUM(BB22,BB23,BB24) -> 4127.054 | BC25: =SUM(BC22,BC23,BC24) -> 4209.5951 | BD25: =SUM(BD22,BD23,BD24) -> 4293.787 | ... BG25: =SUM(BG22,BG23,BG24) -> 4556.6011 | BL25: EBITDA | BM25: =SUM(BM22,BM23,BM24) -> 3738 | BN25: =SUM(BN22,BN23,BN24) -> 3812.76 | BO25: =SUM(BO22,BO23,BO24) -> 3871.2703 | BP25: =SUM(BP22,BP23,BP24) -> 3693.1078 | BQ25: =SUM(BQ22,BQ23,BQ24) -> 2714.4039 | BR25: =SUM(BR22,BR23,BR24) -> 3505.5412 | BS25: =SUM(BS22,BS23,BS24) -> 3488.9362 | BT25: =SUM(BT22,BT23,BT24) -> 3471.5656 | ... BW25: =SUM(BW22,BW23,BW24) -> 3414.683
B26: COGS savings | C26: =R26+AH26 -> 0 | D26: =S26+AI26 -> 0 | E26: =T26+AJ26 -> 0 | F26: =U26+AK26 -> 0 | G26: =V26+AL26 -> 0 | H26: =W26+AM26 -> 0 | I26: =X26+AN26 -> 0 | J26: =Y26+AO26 -> 0 | ... M26: =AB26+AR26 -> 0 | Q26: COGS savings | S26: =Decisions!BG98 -> 0 | T26: =Decisions!BH98 -> 0 | U26: =Decisions!BI98 -> 0 | V26: =Decisions!BJ98 -> 0 | W26: =Decisions!BK98 -> 0 | X26: =Decisions!BL98 -> 0 | Y26: =Decisions!BM98 -> 0 | Z26: =Decisions!BN98 -> 0 | ... AB26: =Decisions!BP98 -> 0 | AG26: COGS savings | AV26: COGS savings | BL26: COGS savings
B27: Manufacturing OH savings | D27: =S27+AI27 -> 0 | E27: =T27+AJ27 -> 0 | F27: =U27+AK27 -> 0 | G27: =V27+AL27 -> 0 | H27: =W27+AM27 -> 0 | I27: =X27+AN27 -> 0 | J27: =Y27+AO27 -> 0 | K27: =Z27+AP27 -> 0 | ... M27: =AB27+AR27 -> 0 | Q27: Manufacturing OH savings | S27: =Decisions!BG99 -> 0 | T27: =Decisions!BH99 -> 0 | U27: =Decisions!BI99 -> 0 | V27: =Decisions!BJ99 -> 0 | W27: =Decisions!BK99 -> 0 | X27: =Decisions!BL99 -> 0 | Y27: =Decisions!BM99 -> 0 | Z27: =Decisions!BN99 -> 0 | ... AB27: =Decisions!BP99 -> 0 | AG27: Manufacturing OH savings | AV27: Manufacturing OH savings
B28: SG&A savings | C28: =R28+AH28 -> 0 | D28: =S28+AI28 -> 0 | E28: =T28+AJ28 -> 0 | F28: =U28+AK28 -> 0 | G28: =V28+AL28 -> 0 | H28: =W28+AM28 -> 0 | I28: =X28+AN28 -> 0 | J28: =Y28+AO28 -> 0 | ... M28: =AB28+AR28 -> 0 | Q28: SG&A savings | S28: =Decisions!BG100 -> 0 | T28: =Decisions!BH100 -> 0 | U28: =Decisions!BI100 -> 0 | V28: =Decisions!BJ100 -> 0 | W28: =Decisions!BK100 -> 0 | X28: =Decisions!BL100 -> 0 | Y28: =Decisions!BM100 -> 0 | Z28: =Decisions!BN100 -> 0 | ... AB28: =Decisions!BP100 -> 0 | AG28: SG&A savings | AV28: SG&A savings | BL28: SG&A savings
B29: Synergies | Q29: Synergies | S29: =Decisions!BG101 -> 0 | T29: =Decisions!BH101 -> 0 | U29: =Decisions!BI101 -> 0 | V29: =Decisions!BJ101 -> 0 | W29: =Decisions!BK101 -> 240 | X29: =Decisions!BL101 -> 240 | Y29: =Decisions!BM101 -> 240 | Z29: =Decisions!BN101 -> 240 | ... AB29: =Decisions!BP101 -> 240 | AG29: Synergies | AV29: Synergies
B30: EBITDA | C30: =SUM(C25:C29) -> 3738 | D30: =SUM(D25:D29) -> 3812.76 | E30: =SUM(E25:E29) -> 3871.2703 | F30: =SUM(F25:F29) -> 3693.1078 | G30: =SUM(G25:G29) -> 2714.4039 | H30: =SUM(H25:H29) -> 4705.5412 | I30: =SUM(I25:I29) -> 4808.9362 | J30: =SUM(J25:J29) -> 4923.5656 | ... M30: =SUM(M25:M29) -> 5347.295 | O30: =SUM(D30:M30)-AD30-AT30 -> -1440 | Q30: EBITDA | S30: =SUM(S25:S29) -> 0 | T30: =SUM(T25:T29) -> 0 | U30: =SUM(U25:U29) -> 0 | V30: =SUM(V25:V29) -> 0 | W30: =SUM(W25:W29) -> 1440 | X30: =SUM(X25:X29) -> 1560 | Y30: =SUM(Y25:Y29) -> 1692 | Z30: =SUM(Z25:Z29) -> 1837.2 | ... AB30: =SUM(AB25:AB29) -> 2172.612 | AD30: =SUM(S30:AB30) -> 10698.732 | AG30: EBITDA | AI30: =SUM(AI25:AI29) -> 3812.76 | AJ30: =SUM(AJ25:AJ29) -> 3871.2703 | AK30: =SUM(AK25:AK29) -> 3693.1078 | AL30: =SUM(AL25:AL29) -> 2714.4039 | AM30: =SUM(AM25:AM29) -> 3505.5412 | AN30: =SUM(AN25:AN29) -> 3488.9362 | AO30: =SUM(AO25:AO29) -> 3471.5656 | AP30: =SUM(AP25:AP29) -> 3453.4118 | ... AR30: =SUM(AR25:AR29) -> 3414.683 | AT30: =SUM(AI30:AR30) -> 34860.137 | AV30: EBITDA | AW30: =AW26+AW25 -> 3738 | AX30: =SUM(AX25:AX28) -> 3812.76 | AY30: =SUM(AY25:AY28) -> 3889.0152 | AZ30: =SUM(AZ25:AZ28) -> 3966.7955 | BA30: =SUM(BA25:BA28) -> 4046.1314 | BB30: =SUM(BB25:BB28) -> 4127.054 | BC30: =SUM(BC25:BC28) -> 4209.5951 | BD30: =SUM(BD25:BD28) -> 4293.787 | BE30: =SUM(BE25:BE28) -> 4379.6628 | ... BG30: =SUM(BG25:BG28) -> 4556.6011 | BL30: EBITDA | BM30: =SUM(BM25,BM26,BM28) -> 3738 | BN30: =SUM(BN25,BN26,BN28) -> 3812.76 | BO30: =SUM(BO25,BO26,BO28) -> 3871.2703 | BP30: =SUM(BP25,BP26,BP28) -> 3693.1078 | BQ30: =SUM(BQ25,BQ26,BQ28) -> 2714.4039 | BR30: =SUM(BR25,BR26,BR28) -> 3505.5412 | BS30: =SUM(BS25,BS26,BS28) -> 3488.9362 | BT30: =SUM(BT25,BT26,BT28) -> 3471.5656 | ... BW30: =SUM(BW25,BW26,BW28) -> 3414.683
B31: D&A | D31: =S31+AI31 -> -1747.7088 | E31: =T31+AJ31 -> -1777.4198 | F31: =U31+AK31 -> -1804.0811 | G31: =V31+AL31 -> -1517.2322 | H31: =W31+AM31 -> -2093.6445 | I31: =X31+AN31 -> -2134.5127 | J31: =Y31+AO31 -> -2178.6253 | K31: =Z31+AP31 -> -2226.3024 | ... M31: =AB31+AR31 -> -2333.7944 | Q31: D&A | S31: =S36 -> 0 | T31: =T36 -> 0 | U31: =U36 -> 0 | V31: =V36 -> 0 | W31: =W36 -> -320 | X31: =X36 -> -352 | Y31: =Y36 -> -387.2 | Z31: =Z36 -> -425.92 | ... AB31: =AB36 -> -515.3632 | AG31: D&A | AH31: =AW31 -> -1622 | AI31: =AI36 -> -1747.7088 | AJ31: =AJ36 -> -1777.4198 | AK31: =AK36 -> -1804.0811 | AL31: =AL36 -> -1517.2322 | AM31: =AM36 -> -1773.6445 | AN31: =AN36 -> -1782.5127 | AO31: =AO36 -> -1791.4253 | AP31: =AP36 -> -1800.3824 | ... AR31: =AR36 -> -1818.4312 | AV31: D&A | AW31: =Baseline!C9+Baseline!C10 -> -1622 | AX31: =AX36 -> -1747.7088 | AY31: =AY36 -> -1782.663 | AZ31: =AZ36 -> -1818.3162 | BA31: =BA36 -> -1854.6826 | BB31: =BB36 -> -1891.7762 | BC31: =BC36 -> -1929.6117 | BD31: =BD36 -> -1968.204 | BE31: =BE36 -> -2007.568 | ... BG31: =BG36 -> -2088.6738 | BL31: D&A | BM31: =AW31 -> -1622 | BN31: =BN36 -> -1747.7088 | BO31: =BO36 -> -1777.4198 | BP31: =BP36 -> -1804.0811 | BQ31: =BQ36 -> -1517.2322 | BR31: =BR36 -> -1773.6445 | BS31: =BS36 -> -1782.5127 | BT31: =BT36 -> -1791.4253 | BU31: =BU36 -> -1800.3824 | ... BW31: =BW36 -> -1818.4312
B32: EBIT operating | C32: =C30+C31 -> 3738 | D32: =D30+D31 -> 2065.0512 | E32: =E30+E31 -> 2093.8504 | F32: =F30+F31 -> 1889.0267 | G32: =G30+G31 -> 1197.1717 | H32: =H30+H31 -> 2611.8967 | I32: =I30+I31 -> 2674.4235 | J32: =J30+J31 -> 2744.9403 | ... M32: =M30+M31 -> 3013.5006 | N32: =M32*(1+$AW$10) -> 3073.7706 | O32: =SUM(D32:M32)-AD32-AT32 -> -1440 | P32: check | Q32: EBIT | S32: =S30+S31 -> 0 | T32: =T30+T31 -> 0 | U32: =U30+U31 -> 0 | V32: =V30+V31 -> 0 | W32: =W30+W31 -> 1120 | X32: =X30+X31 -> 1208 | Y32: =Y30+Y31 -> 1304.8 | Z32: =Z30+Z31 -> 1411.28 | ... AB32: =AB30+AB31 -> 1657.2488 | AC32: =AB32*(1+$AW$10) -> 1690.3938 | AD32: =SUM(S32:AB32) -> 8229.7368 | AG32: EBIT | AH32: =AH30+AH31 -> -1622 | AI32: =AI30+AI31 -> 2065.0512 | AJ32: =AJ30+AJ31 -> 2093.8504 | AK32: =AK30+AK31 -> 1889.0267 | AL32: =AL30+AL31 -> 1197.1717 | AM32: =AM30+AM31 -> 1731.8967 | AN32: =AN30+AN31 -> 1706.4235 | AO32: =AO30+AO31 -> 1680.1403 | ... AR32: =AR30+AR31 -> 1596.2518 | AS32: =AR32*(1+$AW$10) -> 1628.1768 | AT32: =SUM(AI32:AR32) -> 17237.914 | AV32: EBIT | AW32: =AW30+AW31 -> 2116 | AX32: =AX30+AX31 -> 2065.0512 | AY32: =AY30+AY31 -> 2106.3522 | AZ32: =AZ30+AZ31 -> 2148.4793 | BA32: =BA30+BA31 -> 2191.4489 | BB32: =BB30+BB31 -> 2235.2778 | BC32: =BC30+BC31 -> 2279.9834 | BD32: =BD30+BD31 -> 2325.5831 | ... BG32: =BG30+BG31 -> 2467.9273 | BH32: =BG32*(1+$AW$10) -> 2517.2859 | BL32: EBIT | BM32: =BM30+BM31 -> 2116 | BN32: =BN30+BN31 -> 2065.0512 | BO32: =BO30+BO31 -> 2093.8504 | BP32: =BP30+BP31 -> 1889.0267 | BQ32: =BQ30+BQ31 -> 1197.1717 | BR32: =BR30+BR31 -> 1731.8967 | BS32: =BS30+BS31 -> 1706.4235 | BT32: =BT30+BT31 -> 1680.1403 | ... BW32: =BW30+BW31 -> 1596.2518 | BX32: =BW32*(1+$AW$10) -> 1628.1768
B33: =B16 -> Implementation Cost | C33: =R33+AH33 -> 0 | D33: =S33+AI33 -> 0 | E33: =T33+AJ33 -> 0 | F33: =U33+AK33 -> 0 | G33: =V33+AL33 -> 0 | H33: =W33+AM33 -> 0 | I33: =X33+AN33 -> 0 | J33: =Y33+AO33 -> 0 | ... M33: =AB33+AR33 -> 0 | Q33: =Q16 -> Implementation Cost | S33: =S16 -> 0 | T33: =T16 -> 0 | U33: =U16 -> 0 | V33: =V16 -> 0 | W33: =W16 -> 0 | X33: =X16 -> 0 | Y33: =Y16 -> 0 | Z33: =Z16 -> 0 | ... AB33: =AB16 -> 0 | AG33: Non-operating expenses | AI33: =AI16 -> 0 | AJ33: =AJ16 -> 0 | AK33: =AK16 -> 0 | AL33: =AL16 -> 0 | AM33: =AM16 -> 0 | AN33: =AN16 -> 0 | AO33: =AO16 -> 0 | AP33: =AP16 -> 0 | ... AR33: =AR16 -> 0 | AV33: Non-operating expenses | AX33: =AX16 -> 0 | AY33: =AY16 -> 0 | AZ33: =AZ16 -> 0 | BA33: =BA16 -> 0 | BB33: =BB16 -> 0 | BC33: =BC16 -> 0 | BD33: =BD16 -> 0 | BE33: =BE16 -> 0 | ... BG33: =BG16 -> 0 | BL33: Non-operating expenses
B34: Taxes | D34: =MIN(0,-SUM(D32,D33)*$R$34) -> -454.31126 | E34: =MIN(0,-SUM(E32,E33)*$R$34) -> -460.64709 | F34: =MIN(0,-SUM(F32,F33)*$R$34) -> -415.58587 | G34: =MIN(0,-SUM(G32,G33)*$R$34) -> -263.37777 | H34: =MIN(0,-SUM(H32,H33)*$R$34) -> -574.61727 | I34: =MIN(0,-SUM(I32,I33)*$R$34) -> -588.37317 | J34: =MIN(0,-SUM(J32,J33)*$R$34) -> -603.88687 | K34: =MIN(0,-SUM(K32,K33)*$R$34) -> -621.34807 | ... N34: =MIN(0,-SUM(N32,N33)*$R$34) -> -676.22953 | O34: =SUM(D34:M34)-AD34-AT34 -> 316.8 | P34: check, tax can differ due to consolidation | Q34: Taxes | R34: =Decisions!$F$41 -> 0.22 | S34: =MIN(0,-SUM(S32,S33)*$R$34) -> 0 | T34: =MIN(0,-SUM(T32,T33)*$R$34) -> 0 | U34: =MIN(0,-SUM(U32,U33)*$R$34) -> 0 | V34: =MIN(0,-SUM(V32,V33)*$R$34) -> 0 | W34: =MIN(0,-SUM(W32,W33)*$R$34) -> -246.4 | X34: =MIN(0,-SUM(X32,X33)*$R$34) -> -265.76 | Y34: =MIN(0,-SUM(Y32,Y33)*$R$34) -> -287.056 | Z34: =MIN(0,-SUM(Z32,Z33)*$R$34) -> -310.4816 | ... AC34: =MIN(0,-SUM(AC32,AC33)*$R$34) -> -371.88663 | AD34: =SUM(S34:AB34) -> -1810.5421 | AG34: Taxes | AI34: =MIN(0,-SUM(AI32,AI33)*$R$34) -> -454.31126 | AJ34: =MIN(0,-SUM(AJ32,AJ33)*$R$34) -> -460.64709 | AK34: =MIN(0,-SUM(AK32,AK33)*$R$34) -> -415.58587 | AL34: =MIN(0,-SUM(AL32,AL33)*$R$34) -> -263.37777 | AM34: =MIN(0,-SUM(AM32,AM33)*$R$34) -> -381.01727 | AN34: =MIN(0,-SUM(AN32,AN33)*$R$34) -> -375.41317 | AO34: =MIN(0,-SUM(AO32,AO33)*$R$34) -> -369.63087 | AP34: =MIN(0,-SUM(AP32,AP33)*$R$34) -> -363.66647 | ... AS34: =MIN(0,-SUM(AS32,AS33)*$R$34) -> -358.1989 | AT34: =SUM(AI34:AR34) -> -3792.3412 | AV34: Taxes | AX34: =MIN(0,-SUM(AX32,AX33)*$R$34) -> -454.31126 | AY34: =MIN(0,-SUM(AY32,AY33)*$R$34) -> -463.39749 | AZ34: =MIN(0,-SUM(AZ32,AZ33)*$R$34) -> -472.66544 | BA34: =MIN(0,-SUM(BA32,BA33)*$R$34) -> -482.11875 | BB34: =MIN(0,-SUM(BB32,BB33)*$R$34) -> -491.76112 | BC34: =MIN(0,-SUM(BC32,BC33)*$R$34) -> -501.59635 | BD34: =MIN(0,-SUM(BD32,BD33)*$R$34) -> -511.62827 | BE34: =MIN(0,-SUM(BE32,BE33)*$R$34) -> -521.86084 | ... BH34: =MIN(0,-SUM(BH32,BH33)*$R$34) -> -553.8029 | BL34: Taxes | BN34: =MIN(0,-SUM(BN32,BN33)*$R$34) -> -454.31126 | BO34: =MIN(0,-SUM(BO32,BO33)*$R$34) -> -460.64709 | BP34: =MIN(0,-SUM(BP32,BP33)*$R$34) -> -415.58587 | BQ34: =MIN(0,-SUM(BQ32,BQ33)*$R$34) -> -263.37777 | BR34: =MIN(0,-SUM(BR32,BR33)*$R$34) -> -381.01727 | BS34: =MIN(0,-SUM(BS32,BS33)*$R$34) -> -375.41317 | BT34: =MIN(0,-SUM(BT32,BT33)*$R$34) -> -369.63087 | BU34: =MIN(0,-SUM(BU32,BU33)*$R$34) -> -363.66647 | ... BX34: =MIN(0,-SUM(BX32,BX33)*$R$34) -> -358.1989
AG35: Net Income
B36: Capex maintenance | C36: =R36 -> 0 | D36: =S36+AI36 -> -1747.7088 | E36: =T36+AJ36 -> -1777.4198 | F36: =U36+AK36 -> -1804.0811 | G36: =V36+AL36 -> -1517.2322 | H36: =W36+AM36 -> -2093.6445 | I36: =X36+AN36 -> -2134.5127 | J36: =Y36+AO36 -> -2178.6253 | K36: =Z36+AP36 -> -2226.3024 | ... M36: =AB36+AR36 -> -2333.7944 | O36: =SUM(D36:M36)-AD36-AT36 -> 0 | P36: check | Q36: Capex maintenance | R36: =Decisions!AO104 -> 0 | S36: =Decisions!BG104 -> 0 | T36: =Decisions!BH104 -> 0 | U36: =Decisions!BI104 -> 0 | V36: =Decisions!BJ104 -> 0 | W36: =Decisions!BK104 -> -320 | X36: =Decisions!BL104 -> -352 | Y36: =Decisions!BM104 -> -387.2 | Z36: =Decisions!BN104 -> -425.92 | ... AB36: =Decisions!BP104 -> -515.3632 | AD36: =SUM(S36:AB36) -> -2468.9952 | AG36: Capex maintenance | AH36: =AW36 -> -1713.44 | AI36: =-AI22*AI66 -> -1747.7088 | AJ36: =-AJ22*AJ66 -> -1777.4198 | AK36: =-AK22*AK66 -> -1804.0811 | AL36: =-AL22*AL66 -> -1517.2322 | AM36: =-AM22*AM66 -> -1773.6445 | AN36: =-AN22*AN66 -> -1782.5127 | AO36: =-AO22*AO66 -> -1791.4253 | AP36: =-AP22*AP66 -> -1800.3824 | ... AR36: =-AR22*AR66 -> -1818.4312 | AT36: =SUM(AI36:AR36) -> -17622.222 | AV36: Capex maintenance | AW36: =Baseline!C15 -> -1713.44 | AX36: =-AX22*AX66 -> -1747.7088 | AY36: =-AY22*AY66 -> -1782.663 | AZ36: =-AZ22*AZ66 -> -1818.3162 | BA36: =-BA22*BA66 -> -1854.6826 | BB36: =-BB22*BB66 -> -1891.7762 | BC36: =-BC22*BC66 -> -1929.6117 | BD36: =-BD22*BD66 -> -1968.204 | BE36: =-BE22*BE66 -> -2007.568 | ... BG36: =-BG22*BG66 -> -2088.6738 | BL36: Capex maintenance | BM36: =AH36 -> -1713.44 | BN36: =-BN22*BN66 -> -1747.7088 | BO36: =-BO22*BO66 -> -1777.4198 | BP36: =-BP22*BP66 -> -1804.0811 | BQ36: =-BQ22*BQ66 -> -1517.2322 | BR36: =-BR22*BR66 -> -1773.6445 | BS36: =-BS22*BS66 -> -1782.5127 | BT36: =-BT22*BT66 -> -1791.4253 | BU36: =-BU22*BU66 -> -1800.3824 | ... BW36: =-BW22*BW66 -> -1818.4312
